Workbook

Sheet Start Here
B2: BLOCKY LEAGUE · ECONOMY REVIEW
B5: The game has a viable free route. Fix repeat payouts and card-sale inflation before raising prices. Coins develop the club; gems buy guaranteed identities, permanent passes and optional shortcuts.
B8: HOW TO USE: blue cells in Goals are editable. Green cells recalculate saving time. Source Outputs show exact seeded model results; they do not change when you edit a planning assumption.
B11: WHAT THIS IS: a repeatable planning model, not measured retention, conversion, profit or proof that the game feels fun. Currency totals are gross earnings before spending.
B15: Scenario forecasts, not player telemetry, human playtests or revenue forecasts.
B17: Six minutes per match: four playing minutes at the default two-minute halves, plus an assumed two minutes of menus, stoppages and scenes. Ad watch time excluded.
B19: Results are seeded with stated win/draw rates. Statistics are assumed; classic matches only, so Blitz and Hard challenges may remain incomplete.
B21: All reached free rewards are claimed, and players select each next Journey after completing one. No paid passes, purchases, referrals or gem spending in base cases.
B23: Two live objectives per match are assumed (25 coins, 13 XP); no atmosphere boost. Two keeper saves per match; 20% of matches are assumed A-grade (+5% match coins), all others receive no grade bonus. All income uses actual rule functions.
B25: Coin totals are cumulative gross earning, including the 500-coin welcome, NOT spendable balances after club purchases. Each goal is estimated independently.
B27: Free packs are availability counts, not assumed claims. Earned ticket counts exclude the starting two. Both are tracked separately; cards can improve squads or be sold, not both. Resale table estimates their additional value at fixed squad ratings.
B29: Career prizes, board objectives, academy sales, sponsorship, commercial income, renewals and development spending are separate from these shared-loop scenarios: the career sheets (15 October 2026) simulate them.
... B64: NEW SHEETS: Career By Season (the career simulated season by season), Career Tables (what the checks read), Balance Checks (the bar, the measured value, PASS or FAIL) and Ads (rewarded ads by placement, the no-ad comparison, interstitials a visit).

Sheet Source Outputs
A1: Profile | B1: Day | C1: Matches | D1: Play minutes* | E1: Gross coins | F1: Gross gems | G1: Tickets earned | H1: Free packs available | I1: Journeys completed
A2: Learning, no ads | B2: 1 | C2: 2 | D2: 12 | E2: 1362 | F2: 82 | G2: 1 | H2: 1 | I2: 0
A3: Learning, no ads | B3: 7 | C3: 6 | D3: 36 | E3: 3741 | F3: 114 | G3: 6 | H3: 3 | I3: 0
A4: Learning, no ads | B4: 30 | C4: 26 | D4: 156 | E4: 15004 | F4: 218 | G4: 18 | H4: 13 | I4: 0
A5: Learning, no ads | B5: 60 | C5: 52 | D5: 312 | E5: 30754 | F5: 379 | G5: 31 | H5: 26 | I5: 1
A6: Learning, no ads | B6: 90 | C6: 78 | D6: 468 | E6: 48247 | F6: 527 | G6: 43 | H6: 39 | I6: 2
A7: Casual, no ads | B7: 1 | C7: 2 | D7: 12 | E7: 1409 | F7: 82 | G7: 1 | H7: 1 | I7: 0
A8: Casual, no ads | B8: 7 | C8: 8 | D8: 48 | E8: 5385 | F8: 121 | G8: 7 | H8: 4 | I8: 0
A9: Casual, no ads | B9: 30 | C9: 34 | D9: 204 | E9: 29612 | F9: 409 | G9: 30 | H9: 17 | I9: 1
A10: Casual, no ads | B10: 60 | C10: 68 | D10: 408 | E10: 63396 | F10: 680 | G10: 59 | H10: 34 | I10: 3
A11: Casual, no ads | B11: 90 | C11: 102 | D11: 612 | E11: 89948 | F11: 888 | G11: 82 | H11: 51 | I11: 4
A12: Regular, no ads | B12: 1 | C12: 3 | D12: 18 | E12: 1540 | F12: 82 | G12: 1 | H12: 1 | I12: 0
A13: Regular, no ads | B13: 7 | C13: 21 | D13: 126 | E13: 16373 | F13: 270 | G13: 15 | H13: 7 | I13: 0
... A26: Regular + paid Coin Doubler | B26: 90 | C26: 270 | D26: 1620 | E26: 245688 | F26: 1677 | G26: 161 | H26: 90 | I26: 11
A29: *Includes assumed scene/menu time; excludes ad duration.

Sheet Sources
A1: Profile | B1: Currency | C1: Source | D1: 90-day amount | E1: Source scope
A2: Learning, no ads | B2: Coins | C2: welcome | D2: 500 | E2: Shared play loops; career and card sales shown separately
A3: Learning, no ads | B3: Coins | C3: matches | D3: 4444 | E3: Shared play loops; career and card sales shown separately
A4: Learning, no ads | B4: Coins | C4: calendar | D4: 9450 | E4: Shared play loops; career and card sales shown separately
A5: Learning, no ads | B5: Coins | C5: daily | D5: 4300 | E5: Shared play loops; career and card sales shown separately
A6: Learning, no ads | B6: Coins | C6: weekly | D6: 900 | E6: Shared play loops; career and card sales shown separately
A7: Learning, no ads | B7: Coins | C7: live | D7: 1950 | E7: Shared play loops; career and card sales shown separately
A8: Learning, no ads | B8: Coins | C8: skill | D8: 225 | E8: Shared play loops; career and card sales shown separately
A9: Learning, no ads | B9: Coins | C9: mastery | D9: 7700 | E9: Shared play loops; career and card sales shown separately
A10: Learning, no ads | B10: Coins | C10: journeys | D10: 8920 | E10: Shared play loops; career and card sales shown separately
A11: Learning, no ads | B11: Coins | C11: matchAds | D11: 0 | E11: Shared play loops; career and card sales shown separately
A12: Learning, no ads | B12: Coins | C12: coinAds | D12: 0 | E12: Shared play loops; career and card sales shown separately
A13: Learning, no ads | B13: Coins | C13: streak | D13: 910 | E13: Shared play loops; career and card sales shown separately
... A126: Regular + paid Coin Doubler | B126: Gems | C126: matchOfDay | D126: 201 | E126: Shared play loops; career and card sales shown separately

Sheet Goals
A1: Profile | B1: Goal | C1: Currency | D1: Cost | E1: Starting balance | F1: Gross/day (days31–90) | G1: Share saved for goal | H1: Planning days | I1: Planning matches | J1: Matches / week | K1: Exact no-spend model day
A2: Learning, no ads | B2: Main stand | C2: coins | D2: 800 | E2: 500 | F2: 554.05 | G2: 0.4 | H2: =IF(F2*G2>0,ROUNDUP(MAX(0,D2-E2)/(F2*G2),0),0) -> 2 | I2: =ROUNDUP(H2*J2/7,0) -> 2 | J2: 6 | K2: 1
A3: Learning, no ads | B3: Youth academy | C3: coins | D3: 3000 | E3: 500 | F3: 554.05 | G3: 0.4 | H3: =IF(F3*G3>0,ROUNDUP(MAX(0,D3-E3)/(F3*G3),0),0) -> 12 | I3: =ROUNDUP(H3*J3/7,0) -> 11 | J3: 6 | K3: 6
A4: Learning, no ads | B4: Legendary cosmetic | C4: coins | D4: 7500 | E4: 500 | F4: 554.05 | G4: 0.4 | H4: =IF(F4*G4>0,ROUNDUP(MAX(0,D4-E4)/(F4*G4),0),0) -> 32 | I4: =ROUNDUP(H4*J4/7,0) -> 28 | J4: 6 | K4: 15
A5: Learning, no ads | B5: Whole ground | C5: coins | D5: 35600 | E5: 500 | F5: 554.05 | G5: 0.4 | H5: =IF(F5*G5>0,ROUNDUP(MAX(0,D5-E5)/(F5*G5),0),0) -> 159 | I5: =ROUNDUP(H5*J5/7,0) -> 137 | J5: 6 | K5: 71
A6: Learning, no ads | B6: Local scouting network | C6: gems | D6: 200 | E6: 50 | F6: 5.15 | G6: 0.75 | H6: =IF(F6*G6>0,ROUNDUP(MAX(0,D6-E6)/(F6*G6),0),0) -> 39 | I6: =ROUNDUP(H6*J6/7,0) -> 34 | J6: 6 | K6: 24
A7: Learning, no ads | B7: Signature / permanent pass | C7: gems | D7: 600 | E7: 50 | F7: 5.15 | G7: 0.75 | H7: =IF(F7*G7>0,ROUNDUP(MAX(0,D7-E7)/(F7*G7),0),0) -> 143 | I7: =ROUNDUP(H7*J7/7,0) -> 123 | J7: 6 | K7: Beyond 90 days
A8: Learning, no ads | B8: All scouting networks | C8: gems | D8: 1700 | E8: 50 | F8: 5.15 | G8: 0.75 | H8: =IF(F8*G8>0,ROUNDUP(MAX(0,D8-E8)/(F8*G8),0),0) -> 428 | I8: =ROUNDUP(H8*J8/7,0) -> 367 | J8: 6 | K8: Beyond 90 days
A9: Casual, no ads | B9: Main stand | C9: coins | D9: 800 | E9: 500 | F9: 1005.6 | G9: 0.4 | H9: =IF(F9*G9>0,ROUNDUP(MAX(0,D9-E9)/(F9*G9),0),0) -> 1 | I9: =ROUNDUP(H9*J9/7,0) -> 2 | J9: 8 | K9: 1
A10: Casual, no ads | B10: Youth academy | C10: coins | D10: 3000 | E10: 500 | F10: 1005.6 | G10: 0.4 | H10: =IF(F10*G10>0,ROUNDUP(MAX(0,D10-E10)/(F10*G10),0),0) -> 7 | I10: =ROUNDUP(H10*J10/7,0) -> 8 | J10: 8 | K10: 5
A11: Casual, no ads | B11: Legendary cosmetic | C11: coins | D11: 7500 | E11: 500 | F11: 1005.6 | G11: 0.4 | H11: =IF(F11*G11>0,ROUNDUP(MAX(0,D11-E11)/(F11*G11),0),0) -> 18 | I11: =ROUNDUP(H11*J11/7,0) -> 21 | J11: 8 | K11: 10
A12: Casual, no ads | B12: Whole ground | C12: coins | D12: 35600 | E12: 500 | F12: 1005.6 | G12: 0.4 | H12: =IF(F12*G12>0,ROUNDUP(MAX(0,D12-E12)/(F12*G12),0),0) -> 88 | I12: =ROUNDUP(H12*J12/7,0) -> 101 | J12: 8 | K12: 35
A13: Casual, no ads | B13: Local scouting network | C13: gems | D13: 200 | E13: 50 | F13: 7.9833333 | G13: 0.75 | H13: =IF(F13*G13>0,ROUNDUP(MAX(0,D13-E13)/(F13*G13),0),0) -> 26 | I13: =ROUNDUP(H13*J13/7,0) -> 30 | J13: 8 | K13: 12
A14: Casual, no ads | B14: Signature / permanent pass | C14: gems | D14: 600 | E14: 50 | F14: 7.9833333 | G14: 0.75 | H14: =IF(F14*G14>0,ROUNDUP(MAX(0,D14-E14)/(F14*G14),0),0) -> 92 | I14: =ROUNDUP(H14*J14/7,0) -> 106 | J14: 8 | K14: 49
A15: Casual, no ads | B15: All scouting networks | C15: gems | D15: 1700 | E15: 50 | F15: 7.9833333 | G15: 0.75 | H15: =IF(F15*G15>0,ROUNDUP(MAX(0,D15-E15)/(F15*G15),0),0) -> 276 | I15: =ROUNDUP(H15*J15/7,0) -> 316 | J15: 8 | K15: Beyond 90 days
A16: Regular, no ads | B16: Main stand | C16: coins | D16: 800 | E16: 500 | F16: 2386.6833 | G16: 0.4 | H16: =IF(F16*G16>0,ROUNDUP(MAX(0,D16-E16)/(F16*G16),0),0) -> 1 | I16: =ROUNDUP(H16*J16/7,0) -> 3 | J16: 21 | K16: 1
A17: Regular, no ads | B17: Youth academy | C17: coins | D17: 3000 | E17: 500 | F17: 2386.6833 | G17: 0.4 | H17: =IF(F17*G17>0,ROUNDUP(MAX(0,D17-E17)/(F17*G17),0),0) -> 3 | I17: =ROUNDUP(H17*J17/7,0) -> 9 | J17: 21 | K17: 2
A18: Regular, no ads | B18: Legendary cosmetic | C18: coins | D18: 7500 | E18: 500 | F18: 2386.6833 | G18: 0.4 | H18: =IF(F18*G18>0,ROUNDUP(MAX(0,D18-E18)/(F18*G18),0),0) -> 8 | I18: =ROUNDUP(H18*J18/7,0) -> 24 | J18: 21 | K18: 4
A19: Regular, no ads | B19: Whole ground | C19: coins | D19: 35600 | E19: 500 | F19: 2386.6833 | G19: 0.4 | H19: =IF(F19*G19>0,ROUNDUP(MAX(0,D19-E19)/(F19*G19),0),0) -> 37 | I19: =ROUNDUP(H19*J19/7,0) -> 111 | J19: 21 | K19: 16
A20: Regular, no ads | B20: Local scouting network | C20: gems | D20: 200 | E20: 50 | F20: 15.95 | G20: 0.75 | H20: =IF(F20*G20>0,ROUNDUP(MAX(0,D20-E20)/(F20*G20),0),0) -> 13 | I20: =ROUNDUP(H20*J20/7,0) -> 39 | J20: 21 | K20: 5
A21: Regular, no ads | B21: Signature / permanent pass | C21: gems | D21: 600 | E21: 50 | F21: 15.95 | G21: 0.75 | H21: =IF(F21*G21>0,ROUNDUP(MAX(0,D21-E21)/(F21*G21),0),0) -> 46 | I21: =ROUNDUP(H21*J21/7,0) -> 138 | J21: 21 | K21: 22
A22: Regular, no ads | B22: All scouting networks | C22: gems | D22: 1700 | E22: 50 | F22: 15.95 | G22: 0.75 | H22: =IF(F22*G22>0,ROUNDUP(MAX(0,D22-E22)/(F22*G22),0),0) -> 138 | I22: =ROUNDUP(H22*J22/7,0) -> 414 | J22: 21 | K22: Beyond 90 days
A23: Keen, optional ads | B23: Main stand | C23: coins | D23: 800 | E23: 500 | F23: 3679.9833 | G23: 0.4 | H23: =IF(F23*G23>0,ROUNDUP(MAX(0,D23-E23)/(F23*G23),0),0) -> 1 | I23: =ROUNDUP(H23*J23/7,0) -> 6 | J23: 42 | K23: 1
A24: Keen, optional ads | B24: Youth academy | C24: coins | D24: 3000 | E24: 500 | F24: 3679.9833 | G24: 0.4 | H24: =IF(F24*G24>0,ROUNDUP(MAX(0,D24-E24)/(F24*G24),0),0) -> 2 | I24: =ROUNDUP(H24*J24/7,0) -> 12 | J24: 42 | K24: 1
A25: Keen, optional ads | B25: Legendary cosmetic | C25: coins | D25: 7500 | E25: 500 | F25: 3679.9833 | G25: 0.4 | H25: =IF(F25*G25>0,ROUNDUP(MAX(0,D25-E25)/(F25*G25),0),0) -> 5 | I25: =ROUNDUP(H25*J25/7,0) -> 30 | J25: 42 | K25: 2
A26: Keen, optional ads | B26: Whole ground | C26: coins | D26: 35600 | E26: 500 | F26: 3679.9833 | G26: 0.4 | H26: =IF(F26*G26>0,ROUNDUP(MAX(0,D26-E26)/(F26*G26),0),0) -> 24 | I26: =ROUNDUP(H26*J26/7,0) -> 144 | J26: 42 | K26: 8
A27: Keen, optional ads | B27: Local scouting network | C27: gems | D27: 200 | E27: 50 | F27: 16.766667 | G27: 0.75 | H27: =IF(F27*G27>0,ROUNDUP(MAX(0,D27-E27)/(F27*G27),0),0) -> 12 | I27: =ROUNDUP(H27*J27/7,0) -> 72 | J27: 42 | K27: 3
A28: Keen, optional ads | B28: Signature / permanent pass | C28: gems | D28: 600 | E28: 50 | F28: 16.766667 | G28: 0.75 | H28: =IF(F28*G28>0,ROUNDUP(MAX(0,D28-E28)/(F28*G28),0),0) -> 44 | I28: =ROUNDUP(H28*J28/7,0) -> 264 | J28: 42 | K28: 14
A29: Keen, optional ads | B29: All scouting networks | C29: gems | D29: 1700 | E29: 50 | F29: 16.766667 | G29: 0.75 | H29: =IF(F29*G29>0,ROUNDUP(MAX(0,D29-E29)/(F29*G29),0),0) -> 132 | I29: =ROUNDUP(H29*J29/7,0) -> 792 | J29: 42 | K29: 64
A30: Regular + paid Coin Doubler | B30: Main stand | C30: coins | D30: 800 | E30: 500 | F30: 2758.85 | G30: 0.4 | H30: =IF(F30*G30>0,ROUNDUP(MAX(0,D30-E30)/(F30*G30),0),0) -> 1 | I30: =ROUNDUP(H30*J30/7,0) -> 3 | J30: 21 | K30: 1
A31: Regular + paid Coin Doubler | B31: Youth academy | C31: coins | D31: 3000 | E31: 500 | F31: 2758.85 | G31: 0.4 | H31: =IF(F31*G31>0,ROUNDUP(MAX(0,D31-E31)/(F31*G31),0),0) -> 3 | I31: =ROUNDUP(H31*J31/7,0) -> 9 | J31: 21 | K31: 2
A32: Regular + paid Coin Doubler | B32: Legendary cosmetic | C32: coins | D32: 7500 | E32: 500 | F32: 2758.85 | G32: 0.4 | H32: =IF(F32*G32>0,ROUNDUP(MAX(0,D32-E32)/(F32*G32),0),0) -> 7 | I32: =ROUNDUP(H32*J32/7,0) -> 21 | J32: 21 | K32: 4
A33: Regular + paid Coin Doubler | B33: Whole ground | C33: coins | D33: 35600 | E33: 500 | F33: 2758.85 | G33: 0.4 | H33: =IF(F33*G33>0,ROUNDUP(MAX(0,D33-E33)/(F33*G33),0),0) -> 32 | I33: =ROUNDUP(H33*J33/7,0) -> 96 | J33: 21 | K33: 13
A34: Regular + paid Coin Doubler | B34: Local scouting network | C34: gems | D34: 200 | E34: 50 | F34: 15.95 | G34: 0.75 | H34: =IF(F34*G34>0,ROUNDUP(MAX(0,D34-E34)/(F34*G34),0),0) -> 13 | I34: =ROUNDUP(H34*J34/7,0) -> 39 | J34: 21 | K34: 5
A35: Regular + paid Coin Doubler | B35: Signature / permanent pass | C35: gems | D35: 600 | E35: 50 | F35: 15.95 | G35: 0.75 | H35: =IF(F35*G35>0,ROUNDUP(MAX(0,D35-E35)/(F35*G35),0),0) -> 46 | I35: =ROUNDUP(H35*J35/7,0) -> 138 | J35: 21 | K35: 22
A36: Regular + paid Coin Doubler | B36: All scouting networks | C36: gems | D36: 1700 | E36: 50 | F36: 15.95 | G36: 0.75 | H36: =IF(F36*G36>0,ROUNDUP(MAX(0,D36-E36)/(F36*G36),0),0) -> 138 | I36: =ROUNDUP(H36*J36/7,0) -> 414 | J36: 21 | K36: Beyond 90 days
A39: Each goal is independent. Add build time (1–2 league matchdays) and compete with other spending. Planning days use a steady-rate approximation, not the exact curve.

Sheet Sinks
A1: Category | B1: ID | C1: Item | D1: Coins | E1: Gems | F1: Build matchdays
A2: Staff | B2: assistant:1 | C2: ASSISTANT COACH 1 | D2: 400 | E2: 0 | F2: 0
A3: Staff | B3: assistant:2 | C3: ASSISTANT COACH 2 | D3: 1200 | E3: 0 | F3: 0
A4: Staff | B4: assistant:3 | C4: ASSISTANT COACH 3 | D4: 3000 | E4: 0 | F4: 0
A5: Staff | B5: physio:1 | C5: PHYSIO 1 | D5: 400 | E5: 0 | F5: 0
A6: Staff | B6: physio:2 | C6: PHYSIO 2 | D6: 1200 | E6: 0 | F6: 0
A7: Staff | B7: physio:3 | C7: PHYSIO 3 | D7: 3000 | E7: 0 | F7: 0
A8: Staff | B8: scout1:1 | C8: SCOUT 1 | D8: 300 | E8: 0 | F8: 0
A9: Staff | B9: scout1:2 | C9: SCOUT 2 | D9: 900 | E9: 0 | F9: 0
A10: Staff | B10: scout1:3 | C10: SCOUT 3 | D10: 2200 | E10: 0 | F10: 0
A11: Staff | B11: scout2:1 | C11: SECOND SCOUT 1 | D11: 300 | E11: 0 | F11: 0
A12: Staff | B12: scout2:2 | C12: SECOND SCOUT 2 | D12: 900 | E12: 0 | F12: 0
A13: Staff | B13: scout2:3 | C13: SECOND SCOUT 3 | D13: 2200 | E13: 0 | F13: 0
... A150: Gem sink | B150: dealRefresh | C150: dealRefresh | D150: 0 | E150: 15 | F150: 0

Sheet Store Value
A1: Product | B1: Type | C1: Reference US price | D1: Normal gems | E1: First-buy gems | F1: Coins | G1: Normal gems / US$ | H1: First gems / US$
A2: bl.gems.100 | B2: consumable | C2: 0.99 | D2: 100 | E2: 200 | F2: 0 | G2: =D2/C2 -> 101.0101 | H2: =E2/C2 -> 202.0202
A3: bl.gems.300 | B3: consumable | C3: 2.99 | D3: 330 | E3: 660 | F3: 0 | G3: =D3/C3 -> 110.36789 | H3: =E3/C3 -> 220.73579
A4: bl.gems.500 | B4: consumable | C4: 4.99 | D4: 600 | E4: 1200 | F4: 0 | G4: =D4/C4 -> 120.24048 | H4: =E4/C4 -> 240.48096
A5: bl.gems.1000 | B5: consumable | C5: 9.99 | D5: 1300 | E5: 2600 | F5: 0 | G5: =D5/C5 -> 130.13013 | H5: =E5/C5 -> 260.26026
A6: bl.gems.2000 | B6: consumable | C6: 19.99 | D6: 3000 | E6: 6000 | F6: 0 | G6: =D6/C6 -> 150.07504 | H6: =E6/C6 -> 300.15008
A7: bl.starter | B7: non-consumable | C7: 1.99 | D7: 150 | E7: 150 | F7: 2000 | G7: =D7/C7 -> 75.376884 | H7: =E7/C7 -> 75.376884
A8: bl.noads | B8: non-consumable | C8: 3.99 | D8: 0 | E8: 0 | F8: 0 | G8: =D8/C8 -> 0 | H8: =E8/C8 -> 0
A9: bl.pass | B9: consumable | C9: 3.99 | D9: 0 | E9: 0 | F9: 0 | G9: =D9/C9 -> 0 | H9: =E9/C9 -> 0
A10: bl.doubler | B10: non-consumable | C10: 4.99 | D10: 0 | E10: 0 | F10: 0 | G10: =D10/C10 -> 0 | H10: =E10/C10 -> 0
A11: bl.pro | B11: non-consumable | C11: 9.99 | D11: 600 | E11: 600 | F11: 0 | G11: =D11/C11 -> 60.06006 | H11: =E11/C11 -> 60.06006
A14: Reference USD pricing is not a localized StoreKit quote. The actual store price wins. First-buy bonuses are one-time per pack. Do not claim a blanket best value or fixed percentage saving across currencies. Native IAP product setup and real purchase validation remain release prerequisites.
A18: Permanent pass: 600 gems or reference US$3.99, grants 5,560 coins + 150 gems + 6 items after all tiers. First 660-gem pack costs US$2.99, so the direct cash pass is not always cheapest. Signature collection gives all six items immediately, with no currency rewards.

Sheet Career and Cards
A1: Division / squad OVR | B1: Stadium / kind | C1: Two-goal win / mean resale | D1: 20-goal win / min resale | E1: Max resale | F1: Notes
A2: 8 | B2: 0 | C2: 150 | D2: 165 | F2: Base fee before streak, club boosts, side rewards and spending
A3: 8 | B3: 3 | C3: 195 | D3: 215 | F3: Base fee before streak, club boosts, side rewards and spending
A4: 8 | B4: 5 | C4: 225 | D4: 248 | F4: Base fee before streak, club boosts, side rewards and spending
A5: 6 | B5: 0 | C5: 150 | D5: 165 | F5: Base fee before streak, club boosts, side rewards and spending
A6: 6 | B6: 3 | C6: 195 | D6: 215 | F6: Base fee before streak, club boosts, side rewards and spending
A7: 6 | B7: 5 | C7: 225 | D7: 248 | F7: Base fee before streak, club boosts, side rewards and spending
A8: 4 | B8: 0 | C8: 230 | D8: 245 | F8: Base fee before streak, club boosts, side rewards and spending
A9: 4 | B9: 3 | C9: 299 | D9: 319 | F9: Base fee before streak, club boosts, side rewards and spending
A10: 4 | B10: 5 | C10: 345 | D10: 368 | F10: Base fee before streak, club boosts, side rewards and spending
A11: 2 | B11: 0 | C11: 310 | D11: 325 | F11: Base fee before streak, club boosts, side rewards and spending
A12: 2 | B12: 3 | C12: 403 | D12: 423 | F12: Base fee before streak, club boosts, side rewards and spending
A13: 2 | B13: 5 | C13: 465 | D13: 488 | F13: Base fee before streak, club boosts, side rewards and spending
... A16: 1 | B16: 5 | C16: 525 | D16: 548 | F16: Base fee before streak, club boosts, side rewards and spending
A17: 41 | B17: Scout card | C17: 90.6 | D17: 75 | E17: 250 | F17: 1,000 draws. Previous uncapped mean: 205.6. Sell or use for squad, never both.
A18: 65 | B18: Scout card | C18: 90.6 | D18: 75 | E18: 250 | F18: 1,000 draws. Previous uncapped mean: 502.4. Sell or use for squad, never both.
A19: 90 | B19: Scout card | C19: 90.6 | D19: 75 | E19: 250 | F19: 1,000 draws. Previous uncapped mean: 945.4. Sell or use for squad, never both.
A20: Commercial level 1 | B20: Fee 400 | C20: 10 | D20: Wage 10 | E20: Home +40 | F20: Net per league match before sponsor, assuming half home.
A21: Commercial level 2 | B21: Fee 1000 | C21: 21 | D21: Wage 24 | E21: Home +90 | F21: Net per league match before sponsor, assuming half home.
A22: Commercial level 3 | B22: Fee 2000 | C22: 45 | D22: Wage 40 | E22: Home +170 | F22: Net per league match before sponsor, assuming half home.
A25: Career cashflow also includes sponsor and commercial income, cup/season/board prizes and player sales; staff wages, renewals, training and purchases consume it. These variable choices are not included in the shared-loop totals. Full care is taken to keep prize multipliers separate.

Sheet 90 Day Ledger
A1: Profile | B1: Day | C1: Date | D1: Matches | E1: Minutes | F1: Coins | G1: Gems | H1: Tickets | I1: Free packs | J1: Journeys
A2: Learning, no ads | B2: 1 | C2: 2026-10-05 | D2: 2 | E2: 12 | F2: 1362 | G2: 82 | H2: 1 | I2: 1 | J2: 0
A3: Learning, no ads | B3: 2 | C3: 2026-10-06 | D3: 2 | E3: 12 | F3: 1362 | G3: 82 | H3: 1 | I3: 1 | J3: 0
A4: Learning, no ads | B4: 3 | C4: 2026-10-07 | D4: 4 | E4: 24 | F4: 2907 | G4: 87 | H4: 5 | I4: 2 | J4: 0
A5: Learning, no ads | B5: 4 | C5: 2026-10-08 | D5: 4 | E5: 24 | F5: 2907 | G5: 87 | H5: 5 | I5: 2 | J5: 0
A6: Learning, no ads | B6: 5 | C6: 2026-10-09 | D6: 4 | E6: 24 | F6: 2907 | G6: 87 | H6: 5 | I6: 2 | J6: 0
A7: Learning, no ads | B7: 6 | C7: 2026-10-10 | D7: 6 | E7: 36 | F7: 3741 | G7: 114 | H7: 6 | I7: 3 | J7: 0
A8: Learning, no ads | B8: 7 | C8: 2026-10-11 | D8: 6 | E8: 36 | F8: 3741 | G8: 114 | H8: 6 | I8: 3 | J8: 0
A9: Learning, no ads | B9: 8 | C9: 2026-10-12 | D9: 8 | E9: 48 | F9: 4602 | G9: 119 | H9: 7 | I9: 4 | J9: 0
A10: Learning, no ads | B10: 9 | C10: 2026-10-13 | D10: 8 | E10: 48 | F10: 4602 | G10: 119 | H10: 7 | I10: 4 | J10: 0
A11: Learning, no ads | B11: 10 | C11: 2026-10-14 | D11: 10 | E11: 60 | F11: 5684 | G11: 131 | H11: 9 | I11: 5 | J11: 0
A12: Learning, no ads | B12: 11 | C12: 2026-10-15 | D12: 10 | E12: 60 | F12: 5684 | G12: 131 | H12: 9 | I12: 5 | J12: 0
A13: Learning, no ads | B13: 12 | C13: 2026-10-16 | D13: 10 | E13: 60 | F13: 5684 | G13: 131 | H13: 9 | I13: 5 | J13: 0
... A451: Regular + paid Coin Doubler | B451: 90 | C451: 2027-01-02 | D451: 270 | E451: 1620 | F451: 245688 | G451: 1677 | H451: 161 | I451: 90 | J451: 11

Sheet Checks and Limits
A1: Item | B1: Result / limit
A2: Source reconciliation | B2: Every model coin/gem source sums to its final total; deterministic seeds are repeatable.
A3: Modeled uncertainty | B3: 20 seeds per profile. These are scenario sensitivity ranges, not confidence intervals.
A4: Referral promise | B4: 1,000 coins + 50 gems for each qualifying side. Up to20 invited friends plus one welcome receipt; unchanged.
A5: Offline trust | B5: Local saves and device dates remain client-authoritative. Rewind protection closes simple reset farming; it is not server anti-cheat.
A6: Date correction | B6: A claim made with the phone clock in the future stays unavailable until its recorded day passes. A trusted-time recovery flow is not included.
A7: Native payments | B7: Production IAP products/ad units and end-to-end purchases must be configured and tested before public monetization.
A8: Evergreen limits | B8: The12 Journeys are permanent, finite content. Career play can continue; a finite shipped catalogue cannot guarantee endless demand or revenue.
A9: Visual QA | B9: This workbook and code/CLI checks do not constitute rendered or device visual testing.
A11: learning | B11: 90-day range: 46,809–52,932 coins; 504–587 gems
A12: casual | B12: 90-day range: 78,968–89,948 coins; 798–939 gems
A13: regular | B13: 90-day range: 196,908–211,382 coins; 1,614–1,677 gems
... A15: doubler | B15: 90-day range: 225,602–245,688 coins; 1,614–1,677 gems

Sheet Coming Back
A1: Profile | B1: Day | C1: Coins before | D1: Coins after | E1: Coins change | F1: Gems before | G1: Gems after | H1: Gems change | I1: Looks handed over (coin value) | J1: Ground level | K1: Office coins an hour | L1: Play streak day
A2: Learning, no ads | B2: 1 | C2: 1242 | D2: 1362 | E2: =IF(C2>0,D2/C2-1,0) -> 0.096618357 | F2: 79 | G2: 82 | H2: =IF(F2>0,G2/F2-1,0) -> 0.037974684 | I2: 0 | J2: 0 | K2: 16 | L2: 1
A3: Learning, no ads | B3: 7 | C3: 3315 | D3: 3741 | E3: =IF(C3>0,D3/C3-1,0) -> 0.12850679 | F3: 96 | G3: 114 | H3: =IF(F3>0,G3/F3-1,0) -> 0.1875 | I3: 450 | J3: 1 | K3: 20 | L3: 1
A4: Learning, no ads | B4: 30 | C4: 12520 | D4: 15004 | E4: =IF(C4>0,D4/C4-1,0) -> 0.19840256 | F4: 192 | G4: 218 | H4: =IF(F4>0,G4/F4-1,0) -> 0.13541667 | I4: 1900 | J4: 2 | K4: 24 | L4: 1
A5: Learning, no ads | B5: 90 | C5: 38389 | D5: 48247 | E5: =IF(C5>0,D5/C5-1,0) -> 0.25679231 | F5: 468 | G5: 527 | H5: =IF(F5>0,G5/F5-1,0) -> 0.12606838 | I5: 1900 | J5: 2 | K5: 33 | L5: 1
A6: Casual, no ads | B6: 1 | C6: 1289 | D6: 1409 | E6: =IF(C6>0,D6/C6-1,0) -> 0.093095423 | F6: 79 | G6: 82 | H6: =IF(F6>0,G6/F6-1,0) -> 0.037974684 | I6: 0 | J6: 0 | K6: 16 | L6: 1
A7: Casual, no ads | B7: 7 | C7: 4679 | D7: 5385 | E7: =IF(C7>0,D7/C7-1,0) -> 0.15088694 | F7: 100 | G7: 121 | H7: =IF(F7>0,G7/F7-1,0) -> 0.21 | I7: 450 | J7: 1 | K7: 20 | L7: 1
A8: Casual, no ads | B8: 30 | C8: 25510 | D8: 29612 | E8: =IF(C8>0,D8/C8-1,0) -> 0.16079969 | F8: 356 | G8: 409 | H8: =IF(F8>0,G8/F8-1,0) -> 0.1488764 | I8: 1900 | J8: 2 | K8: 24 | L8: 2
A9: Casual, no ads | B9: 90 | C9: 73490 | D9: 89948 | E9: =IF(C9>0,D9/C9-1,0) -> 0.22394884 | F9: 757 | G9: 888 | H9: =IF(F9>0,G9/F9-1,0) -> 0.17305152 | I9: 1900 | J9: 4 | K9: 39 | L9: 1
A10: Regular, no ads | B10: 1 | C10: 1420 | D10: 1540 | E10: =IF(C10>0,D10/C10-1,0) -> 0.084507042 | F10: 79 | G10: 82 | H10: =IF(F10>0,G10/F10-1,0) -> 0.037974684 | I10: 0 | J10: 0 | K10: 18 | L10: 1
A11: Regular, no ads | B11: 7 | C11: 14447 | D11: 16373 | E11: =IF(C11>0,D11/C11-1,0) -> 0.13331488 | F11: 222 | G11: 270 | H11: =IF(F11>0,G11/F11-1,0) -> 0.21621622 | I11: 2500 | J11: 2 | K11: 24 | L11: 7
A12: Regular, no ads | B12: 30 | C12: 57259 | D12: 68181 | E12: =IF(C12>0,D12/C12-1,0) -> 0.19074731 | F12: 612 | G12: 720 | H12: =IF(F12>0,G12/F12-1,0) -> 0.17647059 | I12: 5900 | J12: 3 | K12: 36 | L12: 30
A13: Regular, no ads | B13: 90 | C13: 171380 | D13: 211382 | E13: =IF(C13>0,D13/C13-1,0) -> 0.23341113 | F13: 1391 | G13: 1677 | H13: =IF(F13>0,G13/F13-1,0) -> 0.20560748 | I13: 5900 | J13: 5 | K13: 42 | L13: 90
... A21: Regular + paid Coin Doubler | B21: 90 | C21: 205158 | D21: 245688 | E21: =IF(C21>0,D21/C21-1,0) -> 0.19755506 | F21: 1391 | G21: 1677 | H21: =IF(F21>0,G21/F21-1,0) -> 0.20560748 | I21: 5900 | J21: 5 | K21: 42 | L21: 90
A23: Before: the economy of 6 October 2026 (the same seeded matches, the come-back features off). After: the welcome week, the play streak, the match of the day and club income on, claimed as the assumptions on Start Here say. Gross earning before any spending. Looks are items from the shop at their coin price: they are not coins and are never counted as coins.

Sheet Come Back Sources
A1: Welcome week, calendar day | B1: Calendar coins | C1: Calendar gems | D1: Calendar tickets | E1: Extra gems, first time | F1: Extra tickets, first time | G1: Look, first time | H1: Look coin value (paid instead if owned)
A2: Day 1 | B2: 100 | C2: 0 | D2: 0 | E2: 0 | F2: 0 | H2: 0
A3: Day 2 | B3: 150 | C3: 0 | D3: 0 | E3: 0 | F3: 1 | G3: Melon (ball) | H3: 450
A4: Day 3 | B4: 200 | C4: 5 | D4: 0 | E4: 15 | F4: 0 | H4: 0
A5: Day 4 | B5: 250 | C5: 0 | D5: 0 | E5: 0 | F5: 1 | H5: 0
A6: Day 5 | B6: 300 | C6: 0 | D6: 1 | E6: 0 | F6: 0 | G6: Tiger (kit) | H6: 700
A7: Day 6 | B7: 350 | C7: 0 | D7: 0 | E7: 5 | F7: 0 | H7: 0
A8: Day 7 | B8: 400 | C8: 20 | D8: 0 | E8: 0 | F8: 0 | G8: Big Afro (look) | H8: 750
A9: Week total | B9: =SUM(B2:B8) -> 0 | C9: =SUM(C2:C8) -> 0 | D9: =SUM(D2:D8) -> 0 | E9: =SUM(E2:E8) -> 0 | F9: =SUM(F2:F8) -> 0 | H9: =SUM(H2:H8) -> 0
A12: Play streak day | B12: Coins | C12: Gems | D12: Reserved look, once | E12: Look coin value
A13: Day 1 | B13: 20 | C13: 0 | E13: 0
A14: Day 2 | B14: 30 | C14: 0 | E14: 0
A15: Day 3 | B15: 40 | C15: 2 | E15: 0
A16: Day 4 | B16: 50 | C16: 0 | E16: 0
A17: Day 5 | B17: 60 | C17: 3 | E17: 0
A18: Day 6 | B18: 70 | C18: 0 | E18: 0
A19: Day 7 | B19: 80 | C19: 5 | D19: Music Notes (trail) | E19: 600
A20: Day 14 | B20: 80 | C20: 5 | D20: Rainbow (goalfx) | E20: 1400
A21: Day 30 | B21: 80 | C21: 0 | D21: Halo (look) | E21: 2000
A22: One missed day a week is forgiven. A longer break halves the streak; nothing is zeroed.
A25: Weekly, at the steady rate | B25: Value
A26: Match of the day, coins a day | B26: 100
A27: Match of the day, gems a day | B27: 3
A28: Come-back gems a week | B28: 26
A29: Come-back coins a week (match of the day and streak) | B29: 1260
A30: Loop gems a week, apps, with the daily ad | B30: 123
A31: Loop gems a week, apps, no ads | B31: 102
A32: Loop gems a week, portal, every offer | B32: 144
A33: Tuned band for a week of loop gems | B33: 80 to 160
A36: Profile | B36: Currency | C36: Source | D36: 90 day amount | E36: Share of the 90 day total
A37: Learning, no ads | B37: Coins | C37: streak | D37: 910 | E37: 0.018861276
A38: Learning, no ads | B38: Coins | C38: matchOfDay | D38: 1300 | E38: 0.02694468
A39: Learning, no ads | B39: Coins | C39: clubIncome | D39: 7648 | E39: 0.15851763
A40: Learning, no ads | B40: Gems | C40: welcomeWeek | D40: 20 | E40: 0.037950664
A41: Learning, no ads | B41: Gems | C41: streak | D41: 0 | E41: 0
A42: Learning, no ads | B42: Gems | C42: matchOfDay | D42: 39 | E42: 0.074003795
A43: Casual, no ads | B43: Coins | C43: streak | D43: 1390 | E43: 0.015453373
A44: Casual, no ads | B44: Coins | C44: matchOfDay | D44: 2900 | E44: 0.03224085
A45: Casual, no ads | B45: Coins | C45: clubIncome | D45: 12168 | E45: 0.13527816
A46: Casual, no ads | B46: Gems | C46: welcomeWeek | D46: 20 | E46: 0.022522523
...

Sheet Club Income
A1: Ground level | B1: Ticket office, coins an hour | C1: Club shop (megastore) | D1: Commercial manager % | E1: Atmosphere % | F1: Coins an hour | G1: Full office (cap hours x rate)
A2: 0 Park pitch | B2: 16 | C2: 0 | D2: 0 | E2: 0 | F2: =ROUND((B2+C2)*(1+D2+E2),0) -> 16 | G2: =F2*$B$10 -> 128
A3: 1 Main stand | B3: 18 | C3: 0 | D3: 0 | E3: 0 | F3: =ROUND((B3+C3)*(1+D3+E3),0) -> 18 | G3: =F3*$B$10 -> 144
A4: 2 Family stand | B4: 20 | C4: 0 | D4: 0 | E4: 0 | F4: =ROUND((B4+C4)*(1+D4+E4),0) -> 20 | G4: =F4*$B$10 -> 160
A5: 3 Both sides full, floodlights | B5: 22 | C5: 0 | D5: 0 | E5: 0 | F5: =ROUND((B5+C5)*(1+D5+E5),0) -> 22 | G5: =F5*$B$10 -> 176
A6: 4 Both ends | B6: 24 | C6: 0 | D6: 0 | E6: 0 | F6: =ROUND((B6+C6)*(1+D6+E6),0) -> 24 | G6: =F6*$B$10 -> 192
A7: 5 The dome | B7: 26 | C7: 0 | D7: 0 | E7: 0 | F7: =ROUND((B7+C7)*(1+D7+E7),0) -> 26 | G7: =F7*$B$10 -> 208
A8: Everything built | B8: 26 | C8: 5 | D8: 0.3 | E8: 0.1 | F8: =ROUND((B8+C8)*(1+D8+E8),0) -> 43 | G8: =F8*$B$10 -> 344
A10: Cap, hours | B10: 8
A11: Share of coins the modelled club spends on its ground | B11: 0.4
A12: Blue cells are inputs: try the megastore (5), a manager (10%, 20%, 30%) or an atmosphere (up to 10%) on any row. The clock only moves forward and the office stops at the cap, so a week away is one full office, and nothing is ever lost by staying away.
A16: Profile | B16: Days | C16: Office coins a day | D16: Other coins a day | E16: Office share of the rest | F16: Office rate at the end | G16: Full office at the end
A17: Learning, no ads | B17: 1 to 7 | C17: 37 | D17: 426 | E17: =IF(D17>0,C17/D17,0) -> 0.085762144 | F17: 20 | G17: 160
A18: Learning, no ads | B18: 8 to 30 | C18: 75 | D18: 415 | E18: =IF(D18>0,C18/D18,0) -> 0.18122706 | F18: 24 | G18: 192
A19: Learning, no ads | B19: 31 to 90 | C19: 94 | D19: 460 | E19: =IF(D19>0,C19/D19,0) -> 0.20537365 | F19: 33 | G19: 264
A20: Casual, no ads | B20: 1 to 7 | C20: 59 | D20: 638 | E20: =IF(D20>0,C20/D20,0) -> 0.093085701 | F20: 20 | G20: 160
A21: Casual, no ads | B21: 8 to 30 | C21: 102 | D21: 952 | E21: =IF(D21>0,C21/D21,0) -> 0.10671052 | F21: 24 | G21: 192
A22: Casual, no ads | B22: 31 to 90 | C22: 157 | D22: 849 | E22: =IF(D22>0,C22/D22,0) -> 0.18491752 | F22: 39 | G22: 312
A23: Regular, no ads | B23: 1 to 7 | C23: 139 | D23: 2128 | E23: =IF(D23>0,C23/D23,0) -> 0.065516547 | F23: 24 | G23: 192
A24: Regular, no ads | B24: 8 to 30 | C24: 246 | D24: 2007 | E24: =IF(D24>0,C24/D24,0) -> 0.12255157 | F24: 36 | G24: 288
A25: Regular, no ads | B25: 31 to 90 | C25: 328 | D25: 2059 | E25: =IF(D25>0,C25/D25,0) -> 0.15932513 | F25: 42 | G25: 336
A26: Keen, optional ads | B26: 1 to 7 | C26: 279 | D26: 4340 | E26: =IF(D26>0,C26/D26,0) -> 0.064252798 | F26: 20 | G26: 160
A27: Keen, optional ads | B27: 8 to 30 | C27: 580 | D27: 4426 | E27: =IF(D27>0,C27/D27,0) -> 0.13109085 | F27: 42 | G27: 336
A28: Keen, optional ads | B28: 31 to 90 | C28: 672 | D28: 3008 | E28: =IF(D28>0,C28/D28,0) -> 0.22340549 | F28: 42 | G28: 336
... A40: Portal keen, every offer | B40: 31 to 90 | C40: 672 | D40: 3158 | E40: =IF(D40>0,C40/D40,0) -> 0.21279403 | F40: 42 | G40: 336
A41: Guard rail (tests/economyBalance.test.ts): at most about a quarter at any stage; under a fifth for a regular player; under a tenth in week one.
A44: Profile | B44: Level 1, day | C44: Level 2, day | D44: Level 3, day | E44: Level 4, day | F44: Level 5, day | G44: Rate day 1 / 30 / 90
A45: Learning, no ads | B45: 6 | C45: 15 | D45: Beyond the run | E45: Beyond the run | F45: Beyond the run | G45: 16 / 24 / 33
A46: Casual, no ads | B46: 7 | C46: 10 | D46: 50 | E46: 78 | F46: Beyond the run | G46: 16 / 24 / 39
A47: Regular, no ads | B47: 3 | C47: 5 | D47: 22 | E47: 36 | F47: 44 | G47: 18 / 36 / 42
A48: Keen, optional ads | B48: 2 | C48: 3 | D48: 11 | E48: 18 | F48: 22 | G48: 16 / 42 / 42
A49: Regular + paid Coin Doubler | B49: 3 | C49: 4 | D49: 20 | E49: 29 | F49: 39 | G49: 18 / 39 / 42
A50: Portal casual, one ad a visit | B50: 7 | C50: 10 | D50: 50 | E50: 78 | F50: 101 | G50: 16 / 24 / 39
A51: Portal regular, no ads | B51: 3 | C51: 5 | D51: 22 | E51: 36 | F51: 44 | G51: 18 / 36 / 42
A52: Portal keen, every offer | B52: 2 | C52: 3 | D52: 11 | E52: 18 | F52: 22 | G52: 16 / 42 / 42

Sheet Portal
A1: Profile | B1: Day | C1: Gross coins | D1: Gross gems | E1: Gems from FREE GEMS ads (whole run) | F1: Ground level | G1: Office coins an hour
A2: Portal casual, one ad a visit | B2: 1 | C2: 1409 | D2: 85 | F2: 0 | G2: 16
A3: Portal casual, one ad a visit | B3: 7 | C3: 5385 | D3: 133 | F3: 1 | G3: 20
A4: Portal casual, one ad a visit | B4: 30 | C4: 29612 | D4: 460 | F4: 2 | G4: 24
A5: Portal casual, one ad a visit | B5: 90 | C5: 89948 | D5: 1041 | F5: 4 | G5: 39
A6: Portal casual, one ad a visit | B6: 180 | C6: 185268 | D6: 1864 | F6: 5 | G6: 42
A7: Portal casual, one ad a visit | B7: 365 | C7: 333325 | D7: 3234 | E7: 627 | F7: 5 | G7: 42
A8: Portal regular, no ads | B8: 1 | C8: 1540 | D8: 82 | F8: 0 | G8: 18
A9: Portal regular, no ads | B9: 7 | C9: 16373 | D9: 270 | F9: 2 | G9: 24
A10: Portal regular, no ads | B10: 30 | C10: 68181 | D10: 720 | F10: 3 | G10: 36
A11: Portal regular, no ads | B11: 90 | C11: 211382 | D11: 1677 | F11: 5 | G11: 42
A12: Portal regular, no ads | B12: 180 | C12: 354326 | D12: 2723 | F12: 5 | G12: 42
A13: Portal regular, no ads | B13: 365 | C13: 640538 | D13: 4804 | E13: 0 | F13: 5 | G13: 42
A14: Portal keen, every offer | B14: 1 | C14: 3995 | D14: 104 | F14: 0 | G14: 16
A15: Portal keen, every offer | B15: 7 | C15: 33882 | D15: 455 | F15: 2 | G15: 20
A16: Portal keen, every offer | B16: 30 | C16: 152468 | D16: 1179 | F16: 5 | G16: 42
A17: Portal keen, every offer | B17: 90 | C17: 382267 | D17: 2365 | F17: 5 | G17: 42
A18: Portal keen, every offer | B18: 180 | C18: 691862 | D18: 4057 | F18: 5 | G18: 42
A19: Portal keen, every offer | B19: 365 | C19: 1326338 | D19: 7494 | E19: 2190 | F19: 5 | G19: 42
A22: Profile | B22: Goal | C22: Currency | D22: Cost | E22: Day, everything saved for it | F22: Day, planning share (40% coins, 75% gems)
A23: Portal casual, one ad a visit | B23: Local Scouting Network | C23: gems | D23: 200 | E23: 12 | F23: 14
A24: Portal casual, one ad a visit | B24: Club Pass | C24: gems | D24: 600 | E24: 42 | F24: 61
A25: Portal casual, one ad a visit | B25: National Scouting Network (after Local) | C25: gems | D25: 700 | E25: 49 | F25: 73
A26: Portal casual, one ad a visit | B26: World Scouting Network (all three) | C26: gems | D26: 1700 | E26: 162 | F26: 224
A27: Portal casual, one ad a visit | B27: Club Pass and all three networks | C27: gems | D27: 2300 | E27: 231 | F27: 336
A28: Portal casual, one ad a visit | B28: Main stand | C28: coins | D28: 800 | E28: 1 | F28: 1
A29: Portal casual, one ad a visit | B29: Mid look (EPIC, Inferno goal) | C29: coins | D29: 1200 | E29: 1 | F29: 3
A30: Portal casual, one ad a visit | B30: Top look (LEGENDARY, Supernova goal) | C30: coins | D30: 7500 | E30: 10 | F30: 19
A31: Portal casual, one ad a visit | B31: The whole ground | C31: coins | D31: 35600 | E31: 35 | F31: 89
A32: Portal regular, no ads | B32: Local Scouting Network | C32: gems | D32: 200 | E32: 5 | F32: 7
A33: Portal regular, no ads | B33: Club Pass | C33: gems | D33: 600 | E33: 22 | F33: 32
A34: Portal regular, no ads | B34: National Scouting Network (after Local) | C34: gems | D34: 700 | E34: 28 | F34: 40
... A49: Portal keen, every offer | B49: The whole ground | C49: coins | D49: 35600 | E49: 8 | F49: 19
A50: Each goal alone: nothing else bought with that currency. The gem goals are cumulative where the name says so.
A53: FREE GEMS offers a day | B53: Profile | C53: Offers taken a day | D53: Loop gems a week, at most | E53: Gems day 30 | F53: Gems day 90 | G53: Ad gems in 90 days | H53: Club Pass, day | I53: Local network, day | J53: All three networks, day
A54: 1 | B54: Portal casual, one ad a visit | C54: 1 | D54: 123 | E54: 460 | F54: 1041 | G54: 153 | H54: 42 | I54: 12 | J54: 162
A55: 1 | B55: Portal keen, every offer | C55: 1 | D55: 123 | E55: 1089 | F55: 2095 | G55: 270 | H55: 14 | I55: 3 | J55: 64
A56: 2 | B56: Portal casual, one ad a visit | C56: 1 | D56: 144 | E56: 460 | F56: 1041 | G56: 153 | H56: 42 | I56: 12 | J56: 162
A57: 2 | B57: Portal keen, every offer | C57: 2 | D57: 144 | E57: 1179 | F57: 2365 | G57: 540 | H57: 12 | I57: 3 | J57: 55
A58: 3 | B58: Portal casual, one ad a visit | C58: 1 | D58: 165 | E58: 460 | F58: 1041 | G58: 153 | H58: 42 | I58: 12 | J58: 162
...

Sheet Career By Season
A1: Profile | B1: Season | C1: Division | D1: League | E1: Finish | F1: Outcome | G1: Day from | H1: Day to | I1: Matches | J1: Won | K1: Drawn | L1: Lost | M1: Coins in | N1: Coins out | O1: Net (in less out) | P1: Balance at the end | Q1: Lowest balance after spending | R1: IN: match fees | S1: IN: megastore | T1: IN: cup prizes | U1: IN: season prize | V1: IN: board | W1: IN: sponsor | X1: IN: commercial manager | Y1: IN: player sales | Z1: IN: card sales | AA1: IN: shared loops (gift, challenges, week, mastery, Journey, streak, match of the day) | AB1: IN: club income | AC1: IN: ads | AD1: OUT: ground | AE1: OUT: staff fees | AF1: OUT: staff wages | AG1: OUT: wage drain | AH1: OUT: transfers | AI1: OUT: training | AJ1: OUT: contracts | AK1: OUT: other cards | AL1: Club matchday income (fees, megastore, sponsor, commercial) | AM1: Staff wages / club matchday income | AN1: Wages, drain and contracts / coins in | AO1: Player wages a week | AP1: Wage budget | AQ1: Matchdays staff unpaid | AR1: Matchdays a wage drain took coins | AS1: Team rating | AT1: Division par (rivals) | AU1: Squad | AV1: Ground level | AW1: Parts built (of 13) | AX1: Staff levels (of 18) | AY1: Gems in | AZ1: Gems out | BA1: Gems at the end | BB1: Tickets in | BC1: Tickets out | BD1: Cards signed | BE1: Cards sold | BF1: Manager level
A2: Career learning, 45/25/30, no ads | B2: 1 | C2: 8 | D2: PARK LEAGUE | E2: 5 | F2: stayed | G2: 1 | H2: 17 | I2: 15 | J2: 5 | K2: 3 | L2: 7 | M2: 10933 | N2: 10104 | O2: =M2-N2 -> 829 | P2: 1329 | Q2: 50 | R2: 1428 | S2: 0 | T2: 0 | U2: 60 | V2: 0 | W2: 260 | X2: 290 | Y2: 610 | Z2: 700 | AA2: 6385 | AB2: 1200 | AC2: 0 | AD2: 5100 | AE2: 3900 | AF2: 704 | AG2: 0 | AH2: 0 | AI2: 0 | AJ2: 400 | AK2: 0 | AL2: =R2+S2+W2+X2 -> 1978 | AM2: =IF(AL2>0,AF2/AL2,0) -> 0.35591507 | AN2: =IF(M2>0,(AF2+AG2+AJ2+AK2)/M2,0) -> 0.10097869 | AO2: 946 | AP2: 930 | AQ2: 0 | AR2: 0 | AS2: 44 | AT2: 39 | AU2: 21 | AV2: 2 | AW2: 4 | AX2: 7 | AY2: 134 | AZ2: 0 | BA2: 184 | BB2: 9 | BC2: 11 | BD2: 9 | BE2: 9 | BF2: 7
A3: Career learning, 45/25/30, no ads | B3: 2 | C3: 8 | D3: PARK LEAGUE | E3: 2 | F3: promoted | G3: 17 | H3: 38 | I3: 17 | J3: 12 | K3: 0 | L3: 5 | M3: 24239 | N3: 20848 | O3: =M3-N3 -> 3391 | P3: 4720 | Q3: 285 | R3: 3086 | S3: 360 | T3: 90 | U3: 720 | V3: 150 | W3: 410 | X3: 630 | Y3: 3970 | Z3: 1150 | AA3: 11545 | AB3: 2128 | AC3: 0 | AD3: 17700 | AE3: 1200 | AF3: 1348 | AG3: 0 | AH3: 0 | AI3: 0 | AJ3: 600 | AK3: 0 | AL3: =R3+S3+W3+X3 -> 4486 | AM3: =IF(AL3>0,AF3/AL3,0) -> 0.30049041 | AN3: =IF(M3>0,(AF3+AG3+AJ3+AK3)/M3,0) -> 0.080366352 | AO3: 975 | AP3: 980 | AQ3: 0 | AR3: 0 | AS3: 53 | AT3: 40 | AU3: 14 | AV3: 3 | AW3: 11 | AX3: 8 | AY3: 192 | AZ3: 200 | BA3: 176 | BB3: 15 | BC3: 15 | BD3: 13 | BE3: 11 | BF3: 10
A4: Career learning, 45/25/30, no ads | B4: 3 | C4: 7 | D4: DISTRICT LEAGUE | E4: 2 | F4: promoted | G4: 38 | H4: 57 | I4: 17 | J4: 8 | K4: 6 | L4: 3 | M4: 21792 | N4: 16070 | O4: =M4-N4 -> 5722 | P4: 10442 | Q4: 833 | R4: 2869 | S4: 540 | T4: 105 | U4: 720 | V4: 120 | W4: 680 | X4: 630 | Y4: 2705 | Z4: 600 | AA4: 10495 | AB4: 2328 | AC4: 0 | AD4: 12800 | AE4: 1200 | AF4: 1690 | AG4: 0 | AH4: 0 | AI4: 0 | AJ4: 380 | AK4: 0 | AL4: =R4+S4+W4+X4 -> 4719 | AM4: =IF(AL4>0,AF4/AL4,0) -> 0.35812672 | AN4: =IF(M4>0,(AF4+AG4+AJ4+AK4)/M4,0) -> 0.094988987 | AO4: 1289 | AP4: 1310 | AQ4: 0 | AR4: 0 | AS4: 59 | AT4: 43 | AU4: 15 | AV4: 5 | AW4: 13 | AX4: 9 | AY4: 153 | AZ4: 0 | BA4: 329 | BB4: 13 | BC4: 11 | BD4: 11 | BE4: 8 | BF4: 12
A5: Career learning, 45/25/30, no ads | B5: 4 | C5: 6 | D5: SUNDAY LEAGUE | E5: 1 | F5: promoted | G5: 57 | H5: 78 | I5: 17 | J5: 14 | K5: 1 | L5: 2 | M5: 30985 | N5: 4202 | O5: =M5-N5 -> 26783 | P5: 37225 | Q5: 9179 | R5: 5029 | S5: 540 | T5: 680 | U5: 1040 | V5: 645 | W5: 960 | X5: 630 | Y5: 5230 | Z5: 1400 | AA5: 12095 | AB5: 2736 | AC5: 0 | AD5: 0 | AE5: 1500 | AF5: 1942 | AG5: 0 | AH5: 0 | AI5: 0 | AJ5: 760 | AK5: 0 | AL5: =R5+S5+W5+X5 -> 7159 | AM5: =IF(AL5>0,AF5/AL5,0) -> 0.27126694 | AN5: =IF(M5>0,(AF5+AG5+AJ5+AK5)/M5,0) -> 0.087203486 | AO5: 1672 | AP5: 1700 | AQ5: 0 | AR5: 0 | AS5: 67 | AT5: 48 | AU5: 15 | AV5: 5 | AW5: 13 | AX5: 10 | AY5: 224 | AZ5: 0 | BA5: 553 | BB5: 16 | BC5: 18 | BD5: 17 | BE5: 10 | BF5: 14
A6: Career learning, 45/25/30, no ads | B6: 5 | C6: 5 | D6: COUNTY LEAGUE | E6: 4 | F6: stayed | G6: 78 | H6: 97 | I6: 17 | J6: 9 | K6: 2 | L6: 6 | M6: 21156 | N6: 8422 | O6: =M6-N6 -> 12734 | P6: 49959 | Q6: 32554 | R6: 3893 | S6: 720 | T6: 850 | U6: 120 | V6: 285 | W6: 1030 | X6: 1110 | Y6: 330 | Z6: 750 | AA6: 9380 | AB6: 2688 | AC6: 0 | AD6: 0 | AE6: 5000 | AF6: 2512 | AG6: 0 | AH6: 0 | AI6: 0 | AJ6: 910 | AK6: 0 | AL6: =R6+S6+W6+X6 -> 6753 | AM6: =IF(AL6>0,AF6/AL6,0) -> 0.37198282 | AN6: =IF(M6>0,(AF6+AG6+AJ6+AK6)/M6,0) -> 0.1617508 | AO6: 2392 | AP6: 2400 | AQ6: 0 | AR6: 0 | AS6: 73 | AT6: 56 | AU6: 19 | AV6: 5 | AW6: 13 | AX6: 12 | AY6: 213 | AZ6: 600 | BA6: 166 | BB6: 7 | BC6: 7 | BD6: 5 | BE6: 10 | BF6: 15
A7: Career learning, 45/25/30, no ads | B7: 6 | C7: 5 | D7: COUNTY LEAGUE | E7: 1 | F7: promoted | G7: 97 | H7: 115 | I7: 16 | J7: 13 | K7: 1 | L7: 2 | M7: 32708 | N7: 3994 | O7: =M7-N7 -> 28714 | P7: 78673 | Q7: 49959 | R7: 6090 | S7: 640 | T7: 50 | U7: 1360 | V7: 540 | W7: 1260 | X7: 1190 | Y7: 6415 | Z7: 525 | AA7: 11950 | AB7: 2688 | AC7: 0 | AD7: 0 | AE7: 0 | AF7: 2604 | AG7: 0 | AH7: 0 | AI7: 0 | AJ7: 1390 | AK7: 0 | AL7: =R7+S7+W7+X7 -> 9180 | AM7: =IF(AL7>0,AF7/AL7,0) -> 0.28366013 | AN7: =IF(M7>0,(AF7+AG7+AJ7+AK7)/M7,0) -> 0.1221108 | AO7: 2315 | AP7: 2450 | AQ7: 0 | AR7: 0 | AS7: 79 | AT7: 56 | AU7: 15 | AV7: 5 | AW7: 13 | AX7: 12 | AY7: 193 | AZ7: 0 | BA7: 359 | BB7: 11 | BC7: 11 | BD7: 12 | BE7: 7 | BF7: 16
A8: Career learning, 45/25/30, no ads | B8: 7 | C8: 4 | D8: NATIONAL LEAGUE | E8: 4 | F8: stayed | G8: 115 | H8: 136 | I8: 17 | J8: 9 | K8: 2 | L8: 6 | M8: 33839 | N8: 7614 | O8: =M8-N8 -> 26225 | P8: 104898 | Q8: 76936 | R8: 5010 | S8: 700 | T8: 1020 | U8: 160 | V8: 345 | W8: 1620 | X8: 1190 | Y8: 9035 | Z8: 525 | AA8: 11210 | AB8: 3024 | AC8: 0 | AD8: 0 | AE8: 3000 | AF8: 2994 | AG8: 0 | AH8: 0 | AI8: 0 | AJ8: 1620 | AK8: 0 | AL8: =R8+S8+W8+X8 -> 8520 | AM8: =IF(AL8>0,AF8/AL8,0) -> 0.35140845 | AN8: =IF(M8>0,(AF8+AG8+AJ8+AK8)/M8,0) -> 0.13635155 | AO8: 3217 | AP8: 3250 | AQ8: 0 | AR8: 0 | AS8: 87 | AT8: 66 | AU8: 17 | AV8: 5 | AW8: 13 | AX8: 13 | AY8: 162 | AZ8: 0 | BA8: 521 | BB8: 15 | BC8: 15 | BD8: 17 | BE8: 7 | BF8: 17
A9: Career learning, 45/25/30, no ads | B9: 8 | C9: 4 | D9: NATIONAL LEAGUE | E9: 1 | F9: promoted | G9: 136 | H9: 155 | I9: 16 | J9: 12 | K9: 3 | L9: 1 | M9: 39403 | N9: 4844 | O9: =M9-N9 -> 34559 | P9: 139457 | Q9: 104898 | R9: 7065 | S9: 800 | T9: 60 | U9: 1680 | V9: 660 | W9: 1680 | X9: 1190 | Y9: 10540 | Z9: 850 | AA9: 12190 | AB9: 2688 | AC9: 0 | AD9: 0 | AE9: 0 | AF9: 3024 | AG9: 0 | AH9: 0 | AI9: 0 | AJ9: 1820 | AK9: 0 | AL9: =R9+S9+W9+X9 -> 10735 | AM9: =IF(AL9>0,AF9/AL9,0) -> 0.28169539 | AN9: =IF(M9>0,(AF9+AG9+AJ9+AK9)/M9,0) -> 0.1229348 | AO9: 3299 | AP9: 3310 | AQ9: 0 | AR9: 0 | AS9: 94 | AT9: 66 | AU9: 15 | AV9: 5 | AW9: 13 | AX9: 13 | AY9: 136 | AZ9: 500 | BA9: 157 | BB9: 12 | BC9: 12 | BD9: 12 | BE9: 8 | BF9: 18
A10: Career learning, 45/25/30, no ads | B10: 9 | C10: 3 | D10: LEAGUE ONE | E10: 1 | F10: promoted | G10: 155 | H10: 174 | I10: 17 | J10: 12 | K10: 1 | L10: 4 | M10: 30824 | N10: 9210 | O10: =M10-N10 -> 21614 | P10: 161071 | Q10: 137417 | R10: 8706 | S10: 1080 | T10: 210 | U10: 2000 | V10: 570 | W10: 1900 | X10: 1190 | Y10: 2510 | Z10: 1125 | AA10: 8845 | AB10: 2688 | AC10: 0 | AD10: 0 | AE10: 3800 | AF10: 3550 | AG10: 0 | AH10: 0 | AI10: 0 | AJ10: 1860 | AK10: 0 | AL10: =R10+S10+W10+X10 -> 12876 | AM10: =IF(AL10>0,AF10/AL10,0) -> 0.27570674 | AN10: =IF(M10>0,(AF10+AG10+AJ10+AK10)/M10,0) -> 0.17551259 | AO10: 4265 | AP10: 4400 | AQ10: 0 | AR10: 0 | AS10: 96 | AT10: 74 | AU10: 19 | AV10: 5 | AW10: 13 | AX10: 15 | AY10: 163 | AZ10: 0 | BA10: 320 | BB10: 11 | BC10: 10 | BD10: 6 | BE10: 12 | BF10: 19
A11: Career regular, 60/20/20, no ads | B11: 1 | C11: 8 | D11: PARK LEAGUE | E11: 2 | F11: promoted | G11: 1 | H11: 6 | I11: 15 | J11: 9 | K11: 1 | L11: 5 | M11: 15437 | N11: 12962 | O11: =M11-N11 -> 2475 | P11: 2975 | Q11: 50 | R11: 2139 | S11: 0 | T11: 0 | U11: 720 | V11: 320 | W11: 260 | X11: 240 | Y11: 1750 | Z11: 550 | AA11: 8610 | AB11: 848 | AC11: 0 | AD11: 8900 | AE11: 2900 | AF11: 772 | AG11: 0 | AH11: 0 | AI11: 0 | AJ11: 390 | AK11: 0 | AL11: =R11+S11+W11+X11 -> 2639 | AM11: =IF(AL11>0,AF11/AL11,0) -> 0.29253505 | AN11: =IF(M11>0,(AF11+AG11+AJ11+AK11)/M11,0) -> 0.075273693 | AO11: 987 | AP11: 1000 | AQ11: 0 | AR11: 0 | AS11: 46 | AT11: 39 | AU11: 20 | AV11: 2 | AW11: 6 | AX11: 6 | AY11: 212 | AZ11: 200 | BA11: 62 | BB11: 14 | BC11: 16 | BD11: 14 | BE11: 7 | BF11: 8
A12: Career regular, 60/20/20, no ads | B12: 2 | C12: 7 | D12: DISTRICT LEAGUE | E12: 2 | F12: promoted | G12: 6 | H12: 11 | I12: 17 | J12: 11 | K12: 1 | L12: 5 | M12: 19226 | N12: 19442 | O12: =M12-N12 -> -216 | P12: 2759 | Q12: 457 | R12: 2964 | S12: 420 | T12: 595 | U12: 720 | V12: 150 | W12: 500 | X12: 530 | Y12: 2330 | Z12: 75 | AA12: 9670 | AB12: 1272 | AC12: 0 | AD12: 13900 | AE12: 3400 | AF12: 1522 | AG12: 0 | AH12: 0 | AI12: 0 | AJ12: 620 | AK12: 0 | AL12: =R12+S12+W12+X12 -> 4414 | AM12: =IF(AL12>0,AF12/AL12,0) -> 0.34481196 | AN12: =IF(M12>0,(AF12+AG12+AJ12+AK12)/M12,0) -> 0.11141163 | AO12: 1302 | AP12: 1310 | AQ12: 0 | AR12: 0 | AS12: 54 | AT12: 43 | AU12: 19 | AV12: 3 | AW12: 10 | AX12: 9 | AY12: 175 | AZ12: 0 | BA12: 237 | BB12: 9 | BC12: 7 | BD12: 11 | BE12: 1 | BF12: 10
A13: Career regular, 60/20/20, no ads | B13: 3 | C13: 6 | D13: SUNDAY LEAGUE | E13: 1 | F13: promoted | G13: 11 | H13: 17 | I13: 17 | J13: 16 | K13: 1 | L13: 0 | M13: 28130 | N13: 17134 | O13: =M13-N13 -> 10996 | P13: 13755 | Q13: 648 | R13: 6699 | S13: 480 | T13: 680 | U13: 1040 | V13: 645 | W13: 920 | X13: 630 | Y13: 3895 | Z13: 225 | AA13: 11180 | AB13: 1736 | AC13: 0 | AD13: 12800 | AE13: 1500 | AF13: 1924 | AG13: 0 | AH13: 0 | AI13: 0 | AJ13: 910 | AK13: 0 | AL13: =R13+S13+W13+X13 -> 8729 | AM13: =IF(AL13>0,AF13/AL13,0) -> 0.22041471 | AN13: =IF(M13>0,(AF13+AG13+AJ13+AK13)/M13,0) -> 0.10074653 | AO13: 1702 | AP13: 1750 | AQ13: 0 | AR13: 0 | AS13: 63 | AT13: 47 | AU13: 18 | AV13: 5 | AW13: 13 | AX13: 10 | AY13: 276 | AZ13: 0 | BA13: 513 | BB13: 11 | BC13: 12 | BD13: 15 | BE13: 3 | BF13: 13
... A138: Career regular, signs every better card, hires everyone | B138: 27 | C138: 1 | D138: ELITE LEAGUE | E138: 2 | F138: stayed | G138: 170 | H138: 177 | I138: 21 | J138: 11 | K138: 4 | L138: 6 | M138: 27610 | N138: 5440 | O138: =M138-N138 -> 22170 | P138: 591967 | Q138: 569797 | R138: 9478 | S138: 1600 | T138: 570 | U138: 2270 | V138: 0 | W138: 2440 | X138: 1190 | Y138: 0 | Z138: 1675 | AA138: 6035 | AB138: 2352 | AC138: 0 | AD138: 0 | AE138: 0 | AF138: 4480 | AG138: 0 | AH138: 0 | AI138: 0 | AJ138: 960 | AK138: 0 | AL138: =R138+S138+W138+X138 -> 14708 | AM138: =IF(AL138>0,AF138/AL138,0) -> 0.30459614 | AN138: =IF(M138>0,(AF138+AG138+AJ138+AK138)/M138,0) -> 0.19703006 | AO138: 4763 | AP138: 7030 | AQ138: 0 | AR138: 0 | AS138: 97 | AT138: 92 | AU138: 21 | AV138: 5 | AW138: 13 | AX138: 18 | AY138: 78 | AZ138: 0 | BA138: 2811 | BB138: 11 | BC138: 10 | BD138: 0 | BE138: 17 | BF138: 31
A140: ROAD TO GLORY played matchday by matchday on the game's own engine for 180 days (seed 15102026): the league, the cups, the week at the club, the staff, the ground, the board and the event cards are the real rules. ASSUMED: who wins. The profile's mix (45/25/30, 60/20/20, 75/15/10) holds when the two elevens are level on Normal; every rating point between them moves 1.5 points of a hundred between wins and defeats (up to 25); Hard (the Championship) takes 10 off the wins and Legend (the Elite League) 20. THE MANAGER: keeps 3 matchdays of staff wages in the wallet; builds the cheapest part of the ground he can; hires staff in order while their wages stay under 50% of what a league matchday brings; opens every pack and signs a card that beats a starter when the wage budget allows, else sells it; signs or trains only when the eleven is under its division's par; buys the Local network, the Club Pass, then the other networks with gems. Everything else is saved: the balance is what is left for looks. Only finished seasons are rows. Not player telemetry.

Sheet Career Tables
A1: Headline by profile
A2: Profile | C2: Days modelled | D2: Seasons finished | E2: Division at the end | F2: Coins earned | G2: Coins spent | H2: Balance at the end | I2: Gems earned | J2: Gems spent | K2: Day every coin sink is paid for | L2: Average fee of a won match
A3: Career learning, 45/25/30, no ads | C3: 180 | D3: 9 | E3: 2 | F3: 252631 | G3: 89512 | H3: 163119 | I3: 1646 | J3: 1300 | K3: Beyond the run | L3: 414
A4: Career regular, 60/20/20, no ads | C4: 180 | D4: 27 | E4: 1 | F4: 853044 | G4: 214962 | H4: 638082 | I4: 4569 | J4: 2300 | K4: 57 | L4: 671
A5: Career strong, 75/15/10, every ad | C5: 180 | D5: 48 | E5: 1 | F5: 2730037 | G5: 377248 | H5: 2352789 | I5: 11582 | J5: 2300 | K5: 25 | L5: 816
A6: Career regular, every ad | C6: 180 | D6: 26 | E6: 1 | F6: 1299805 | G6: 204552 | H6: 1095253 | I6: 5907 | J6: 2300 | K6: 39 | L6: 709
A7: Career regular, signs every better card, hires everyone | C7: 180 | D7: 27 | E7: 1 | F7: 878158 | G7: 273974 | H7: 604184 | I7: 5147 | J7: 2300 | K7: 66 | L7: 672
A9: Promotions
A10: Profile | B10: Promoted to | C10: In season | D10: On day
A11: Career learning, 45/25/30, no ads | B11: Division 7 | C11: 2 | D11: 38
A12: Career learning, 45/25/30, no ads | B12: Division 6 | C12: 3 | D12: 57
A13: Career learning, 45/25/30, no ads | B13: Division 5 | C13: 4 | D13: 78
A14: Career learning, 45/25/30, no ads | B14: Division 4 | C14: 6 | D14: 115
A15: Career learning, 45/25/30, no ads | B15: Division 3 | C15: 8 | D15: 155
A16: Career learning, 45/25/30, no ads | B16: Division 2 | C16: 9 | D16: 174
A17: Career regular, 60/20/20, no ads | B17: Division 7 | C17: 1 | D17: 6
A18: Career regular, 60/20/20, no ads | B18: Division 6 | C18: 2 | D18: 11
A19: Career regular, 60/20/20, no ads | B19: Division 5 | C19: 3 | D19: 17
A20: Career regular, 60/20/20, no ads | B20: Division 4 | C20: 4 | D20: 23
A21: Career regular, 60/20/20, no ads | B21: Division 3 | C21: 5 | D21: 28
A22: Career regular, 60/20/20, no ads | B22: Division 2 | C22: 6 | D22: 34
... A47: Career regular, signs every better card, hires everyone | B47: Division 1 | C47: 26 | D47: 170
A49: Days to each goal
A50: Profile | B50: Goal | C50: Day
A51: Career learning, 45/25/30, no ads | B51: A mid look in the wallet (1,200 coins) | C51: 10
A52: Career learning, 45/25/30, no ads | B52: A top look in the wallet (7,500 coins) | C52: 45
A53: Career learning, 45/25/30, no ads | B53: The whole ground built | C53: 50
A54: Career learning, 45/25/30, no ads | B54: Every member of staff at level 3 | C54: Beyond the run
A55: Career learning, 45/25/30, no ads | B55: Local Scouting Network | C55: 22
A56: Career learning, 45/25/30, no ads | B56: Club Pass | C56: 87
A57: Career learning, 45/25/30, no ads | B57: All three Scouting Networks | C57: Beyond the run
A58: Career regular, 60/20/20, no ads | B58: A mid look in the wallet (1,200 coins) | C58: 4
A59: Career regular, 60/20/20, no ads | B59: A top look in the wallet (7,500 coins) | C59: 13
A60: Career regular, 60/20/20, no ads | B60: The whole ground built | C60: 15
A61: Career regular, 60/20/20, no ads | B61: Every member of staff at level 3 | C61: 34
A62: Career regular, 60/20/20, no ads | B62: Local Scouting Network | C62: 5
A63: Career regular, 60/20/20, no ads | B63: Club Pass | C63: 22
A64: Career regular, 60/20/20, no ads | B64: All three Scouting Networks | C64: 66
A65: Career strong, 75/15/10, every ad | B65: A mid look in the wallet (1,200 coins) | C65: 2
A66: Career strong, 75/15/10, every ad | B66: A top look in the wallet (7,500 coins) | C66: 7
...

Sheet Ads
A1: Rewarded ads taken, by placement (a player who watches every one)
A2: Profile | B2: Placement | C2: Offered | D2: Taken in the run | E2: A day played | F2: Coins | G2: Gems | H2: Coins each | I2: Share of his coins | J2: Share of his gems | K2: What it is worth
A3: Career regular, every ad | B3: Daily gift doubled | C3: 1 a day | D3: 180 | E3: 1 | F3: 44750 | G3: 0 | H3: 249 | I3: 0.034428241 | J3: 0 | K3: the gift's coins again
A4: Career regular, every ad | B4: Full-time bonus | C4: every match | D4: 540 | E4: 3 | F4: 274736 | G4: 0 | H4: 509 | I4: 0.21136709 | J4: 0 | K4: the match fee once more: exactly one match
A5: Career regular, every ad | B5: FREE COINS | C5: 5 a day | D5: 900 | E5: 5 | F5: 67500 | G5: 0 | H5: 75 | I5: 0.051930867 | J5: 0 | K5: 75 coins each
A6: Career regular, every ad | B6: FREE GEMS | C6: 1 a day | D6: 180 | E6: 1 | F6: 0 | G6: 540 | H6: 0 | I6: 0 | J6: 0.091416963 | K6: 3 gems each
A7: Career regular, every ad | B7: One matchday off a build | C7: 1 a day | D7: 10 | E7: 0.055555556 | F7: 0 | G7: 0 | H7: 0 | I7: 0 | J7: 0 | K7: time: 20 gems as a shortcut, pays no currency
A8: Career regular, every ad | B8: Heal a player | C8: 1 a day | D8: 43 | E8: 0.23888889 | F8: 0 | G8: 0 | H8: 0 | I8: 0 | J8: 0 | K8: time: 30 gems as a shortcut, pays no currency
A9: Career regular, every ad | B9: Replay a lost decider | C9: 1 a day | D9: 44 | E9: 0.24444444 | F9: 0 | G9: 0 | H9: 0 | I9: 0 | J9: 0 | K9: a second go at the same tie (50 gems as a shortcut): worth that match at most
A10: Career regular, every ad | B10: A new daily deal | C10: 1 a day | D10: 0 | E10: 0 | F10: 0 | G10: 0 | H10: 0 | I10: 0 | J10: 0 | K10: not modelled: a different look on offer (15 gems as a shortcut), pays no currency
A11: Career strong, 75/15/10, every ad | B11: Daily gift doubled | C11: 1 a day | D11: 180 | E11: 1 | F11: 44750 | G11: 0 | H11: 249 | I11: 0.016391719 | J11: 0 | K11: the gift's coins again
A12: Career strong, 75/15/10, every ad | B12: Full-time bonus | C12: every match | D12: 1080 | E12: 6 | F12: 692796 | G12: 0 | H12: 641 | I12: 0.25376799 | J12: 0 | K12: the match fee once more: exactly one match
A13: Career strong, 75/15/10, every ad | B13: FREE COINS | C13: 5 a day | D13: 900 | E13: 5 | F13: 67500 | G13: 0 | H13: 75 | I13: 0.02472494 | J13: 0 | K13: 75 coins each
A14: Career strong, 75/15/10, every ad | B14: FREE GEMS | C14: 1 a day | D14: 180 | E14: 1 | F14: 0 | G14: 540 | H14: 0 | I14: 0 | J14: 0.046624072 | K14: 3 gems each
... A18: Career strong, 75/15/10, every ad | B18: A new daily deal | C18: 1 a day | D18: 0 | E18: 0 | F18: 0 | G18: 0 | H18: 0 | I18: 0 | J18: 0 | K18: not modelled: a different look on offer (15 gems as a shortcut), pays no currency
A20: Never an ad against every ad: the day each goal is reached (Career regular, three seeds)
A21: Goal | C21: No ads, day | D21: Every ad, day | E21: No ads / every ad
A22: A mid look in the wallet (1,200 coins) | C22: 4 | D22: 3 | E22: =IF(D22>0,C22/D22,0) -> 1.3333333
A23: A top look in the wallet (7,500 coins) | C23: 14 | D23: 10 | E23: =IF(D23>0,C23/D23,0) -> 1.4
A24: The whole ground built | C24: 14.333333 | D24: 10.666667 | E24: =IF(D24>0,C24/D24,0) -> 1.34375
A25: Every member of staff at level 3 | C25: 35.666667 | D25: 35.666667 | E25: =IF(D25>0,C25/D25,0) -> 1
A26: Local Scouting Network | C26: 5 | D26: 4.3333333 | E26: =IF(D26>0,C26/D26,0) -> 1.1538462
A27: Club Pass | C27: 20 | D27: 17 | E27: =IF(D27>0,C27/D27,0) -> 1.1764706
A28: All three Scouting Networks | C28: 68.333333 | D28: 56 | E28: =IF(D28>0,C28/D28,0) -> 1.2202381
A30: Interstitials in a visit (blue cells are inputs)
A31: Input | C31: Value
A32: Minutes from a kick-off to half time | C32: 2.5
A33: Minutes from half time to the next kick-off | C33: 3.5
A34: Minutes the portal asks for between two | C34: 3
A36: Profile | C36: Matches a visit | D36: Minutes a visit | E36: Interstitials, the save's first visit (model) | F36: Interstitials, a later visit (formula) | G36: An hour of play | H36: Rewarded ads a day played
A37: Career learning, 45/25/30, no ads | C37: 2 | D37: =C37*($C$32+$C$33) -> 12 | E37: 0 | F37: =IF(AND($C$32>=$C$34,$C$33>=$C$34),2*C37-1,IF($C$32+$C$33>=$C$34,C37,ROUNDUP(C37*($C$32+$C$33)/$C$34,0))) -> 2 | G37: =IF(D37>0,F37/D37*60,0) -> 10 | H37: 0
A38: Career regular, 60/20/20, no ads | C38: 3 | D38: =C38*($C$32+$C$33) -> 18 | E38: 1 | F38: =IF(AND($C$32>=$C$34,$C$33>=$C$34),2*C38-1,IF($C$32+$C$33>=$C$34,C38,ROUNDUP(C38*($C$32+$C$33)/$C$34,0))) -> 3 | G38: =IF(D38>0,F38/D38*60,0) -> 10 | H38: 0
A39: Career strong, 75/15/10, every ad | C39: 6 | D39: =C39*($C$32+$C$33) -> 36 | E39: 4 | F39: =IF(AND($C$32>=$C$34,$C$33>=$C$34),2*C39-1,IF($C$32+$C$33>=$C$34,C39,ROUNDUP(C39*($C$32+$C$33)/$C$34,0))) -> 6 | G39: =IF(D39>0,F39/D39*60,0) -> 10 | H39: 13.744444
A40: Career regular, every ad | C40: 3 | D40: =C40*($C$32+$C$33) -> 18 | E40: 1 | F40: =IF(AND($C$32>=$C$34,$C$33>=$C$34),2*C40-1,IF($C$32+$C$33>=$C$34,C40,ROUNDUP(C40*($C$32+$C$33)/$C$34,0))) -> 3 | G40: =IF(D40>0,F40/D40*60,0) -> 10 | H40: 10.538889
A42: THE RULE MODELLED: one interstitial before a kick-off, never the first match of a visit; one at half time; none until two matches are finished on the save; and the portal's SDK lets one through every 3 minutes at most. At the default 2 minute halves half time comes 2.5 minutes after a kick-off ad, inside the 3 minutes, so a visit of N matches shows N: the half time of the first match and the kick-off of every later one. One every six minutes, ten an hour. With 3 minute halves both slots clear the gap and it would be 2N - 1. Rewarded ads are the player's choice and are counted apart. MODELLED, NOT BUILT HERE: the welcome sheet's ad doubling the ticket office, HEAL A PLAYER by ad, the replay ad, the half time interstitial. Club Run is not in the career simulation.

Sheet Balance Checks
A1: Area | B1: Check | C1: The bar | D1: Limit | E1: Measured | F1: Result | G1: Before this pass | H1: Unit | I1: What it shows
A2: The model | B2: Every league matchday settles to the coin against the rules read beforehand | C2: No coin unaccounted for | D2: 0 | E2: 0 | F2: =IF(E2<=D2,"PASS","FAIL") -> PASS | H2: coins | I2: Wages, the wage drain, the sponsor, the commercial manager and the season prize, itemised before the engine settles the matchday.
A3: Wages | B3: Matchdays the staff went unpaid, careful manager, all three profiles, every division | C3: Never | D3: 0 | E3: =SUM('Career By Season'!AQ2:AQ10,'Career By Season'!AQ11:AQ37,'Career By Season'!AQ38:AQ85) -> 0 | F3: =IF(E3<=D3,"PASS","FAIL") -> PASS | H3: matchdays | I3: Lowest balance after spending in any season: 50 coins (the wage reserve of a new club).
